좋은 질문이야! `finally`는 `try...catch`만으로도 예외 처리가 가능하지만, **예외 발생 여부와 관계없이 항상 실행해야 하는 코드가 있을 때** 필요해.
## 🔹 `finally`가 필요한 이유

1. **리소스 정리 (Cleanup)**
    - 예를 들어, 데이터베이스 연결을 닫거나, 파일을 닫는 등의 작업을 반드시 수행해야 할 때 사용해.
2. **중요한 코드 실행 보장**
    - 오류가 발생하든 안 하든, 특정 코드가 **무조건 실행되도록** 하고 싶을 때 유용해.

---
## 🎯 예제 1: 파일 닫기 (리소스 정리)

```javascript
function processFile() {
    try {
        console.log("파일을 열었습니다.");
        throw new Error("파일 처리 중 오류 발생!");
    } catch (error) {
        console.error("오류:", error.message);
    } finally {
        console.log("파일을 닫습니다."); // 오류 발생 여부와 상관없이 실행됨
    }
}

processFile();
```

✅ `finally` 없이 `catch`에서 return 해버리면 파일이 닫히지 않을 수 있어.  
✅ `finally`를 사용하면 **오류가 발생하든 안 하든 파일을 닫는 코드가 실행됨**.

---

## 🎯 예제 2: 네트워크 요청 후 로딩 상태 해제
```javascript
async function fetchData() {
    let isLoading = true;
    try {
        let response = await fetch("https://api.example.com/data");
        if (!response.ok) {
            throw new Error("데이터 불러오기 실패");
        }
        let data = await response.json();
        console.log("데이터:", data);
    } catch (error) {
        console.error("오류:", error.message);
    } finally {
        isLoading = false;  // 로딩 상태를 반드시 false로 변경
        console.log("로딩 상태:", isLoading);
    }
}

fetchData();
```

✅ `finally`가 없으면 **에러 발생 시 `isLoading = false`가 실행되지 않을 수도 있음**.  
✅ `finally`를 사용하면 **네트워크 요청 성공/실패에 상관없이 로딩 상태를 정상적으로 변경 가능**.

---
## 🔥 결론
`try...catch`만으로도 예외 처리는 가능하지만,  
📌 **예외 발생 여부와 상관없이 반드시 실행해야 하는 코드**가 있을 때 `finally`를 사용하면 안정적인 코드가 된다!

---
---

# finally와 function
## 🎯 **1. 함수에서 리턴(return)해도 `finally`는 실행됨!**
일반적으로 `return`을 만나면 함수가 즉시 종료되지만,  
`finally` 블록은 **리턴(return) 전에 반드시 실행되는 특수한 블록**이야.
### ✅ 예제: `return`이 있어도 `finally`는 실행됨
```javascript
function testFunction() {
    try {
        console.log("try 블록 실행");
        return "try에서 리턴"; // 여기서 리턴되지만...
    } catch (error) {
        console.log("catch 블록 실행");
    } finally {
        console.log("finally 블록 실행!"); // 리턴 전에 실행됨!
    }
}

console.log(testFunction()); 
```

**🛠 실행 결과:**
```
try 블록 실행  
finally 블록 실행!  
try에서 리턴  
```

✅ **`finally`는 `return`보다 먼저 실행됨!**  
✅ 즉, 함수가 종료되기 전에 **마지막으로 해야 할 작업이 있다면 `finally`를 활용**하면 돼.

---

## 🎯 **2. 함수 내부에서 예외가 발생해도 `finally`는 실행됨**
`try` 블록에서 예외가 발생하면 `catch`로 이동하지만,  
**`finally`는 `catch` 실행 후에도 무조건 실행됨**.

### ✅ 예제: 예외가 발생해도 `finally` 실행됨
```javascript
function testError() {
    try {
        console.log("try 실행");
        throw new Error("강제 오류!");
    } catch (error) {
        console.log("catch 실행:", error.message);
        return "catch에서 리턴"; // 여기서 리턴하지만...
    } finally {
        console.log("finally 실행!"); // 그래도 실행됨!
    }
}

console.log(testError());
```

**🛠 실행 결과:**
```
try 실행  
catch 실행: 강제 오류!  
finally 실행!  
catch에서 리턴  
```

✅ **`catch`에서 리턴하더라도 `finally`는 실행됨!**  
✅ 예외가 발생해도 리소스를 정리하거나 마지막 작업을 수행할 수 있음.

---

## 🎯 **3. 함수가 `throw`로 예외를 던져도 `finally`는 실행됨**
`try` 블록에서 예외를 던지고(`throw`),  
`catch`에서 예외를 다시 던져도(`throw error`),  
**`finally`는 무조건 실행됨**.

### ✅ 예제: `throw`가 있어도 `finally` 실행됨
```javascript
function throwError() {
    try {
        console.log("try 실행");
        throw new Error("오류 발생!");
    } catch (error) {
        console.log("catch 실행:", error.message);
        throw error; // 예외 다시 던지기
    } finally {
        console.log("finally 실행!"); // 예외가 던져져도 실행됨!
    }
}

try {
    throwError();
} catch (error) {
    console.log("외부 catch 실행:", error.message);
}
```

**🛠 실행 결과:**

```
try 실행  
catch 실행: 오류 발생!  
finally 실행!  
외부 catch 실행: 오류 발생!  
```

✅ `throw error;`로 예외를 다시 던졌지만 **`finally`는 실행됨!**  
✅ 함수 내부에서 예외를 던지든 리턴하든, 마지막 정리 작업을 할 수 있음.

---
## 🔥 **결론: `finally`는 함수와 매우 깊은 관련이 있음!**

📌 `finally`는 **리턴(return) 전에 실행**됨.  
📌 예외가 발생하거나, 다시 던져져도(`throw`) **반드시 실행**됨.  
📌 함수 종료 전에 **리소스 정리, 상태 변경, 중요한 작업을 보장**하는 역할을 함.
